<?xml version="1.0"?>
<robot name="wsg_300_120">

  <!-- Base -->
  <link name="base_link">
    <visual>
      <origin xyz="0 0 0" rpy="0 0 0"/>
      <geometry>
        <mesh filename="package://wpg_300_120_description/meshes/base.stl" scale="0.001 0.001 0.001"/>
      </geometry>
    </visual>
    <collision>
      <origin xyz="0 0 0" rpy="0 0 0"/>
      <geometry>
        <mesh filename="package://wpg_300_120_description/meshes/base.stl" scale="0.001 0.001 0.001"/>
      </geometry>
    </collision>
    <inertial>
      <origin xyz="0 0 0"/>
      <mass value="0.5"/>
      <inertia ixx="0.001" ixy="0" ixz="0" iyy="0.001" iyz="0" izz="0.001"/>
    </inertial>
  </link>

  <!-- Left Finger -->
  <link name="left_finger">
    <visual>
      <origin xyz="0 0 0" rpy="0 0 0"/>
      <geometry>
        <mesh filename="package://wpg_300_120_description/meshes/left_finger.stl" scale="0.001 0.001 0.001"/>
      </geometry>
    </visual>
    <collision>
      <origin xyz="0 0 0" rpy="0 0 0"/>
      <geometry>
        <mesh filename="package://wpg_300_120_description/meshes/left_finger.stl" scale="0.001 0.001 0.001"/>
      </geometry>
    </collision>
    <inertial>
      <origin xyz="0 0 0"/>
      <mass value="0.1"/>
      <inertia ixx="0.0001" ixy="0" ixz="0" iyy="0.0001" iyz="0" izz="0.0001"/>
    </inertial>
  </link>

  <!-- Right Finger -->
  <link name="right_finger">
    <visual>
      <origin xyz="0 0 0" rpy="0 0 0"/>
      <geometry>
        <mesh filename="package://wpg_300_120_description/meshes/right_finger.stl" scale="0.001 0.001 0.001"/>
      </geometry>
    </visual>
    <collision>
      <origin xyz="0 0 0" rpy="0 0 0"/>
      <geometry>
        <mesh filename="package://wpg_300_120_description/meshes/right_finger.stl" scale="0.001 0.001 0.001"/>
      </geometry>
    </collision>
    <inertial>
      <origin xyz="0 0 0"/>
      <mass value="0.1"/>
      <inertia ixx="0.0001" ixy="0" ixz="0" iyy="0.0001" iyz="0" izz="0.0001"/>
    </inertial>
  </link>

  <!-- Left finger joint -->
  <joint name="left_finger_joint" type="prismatic">
    <parent link="base_link"/>
    <child link="left_finger"/>
    <origin xyz="0.042 0.0185 0.069" rpy="1.5708 0 -1.5708"/>
    <axis xyz="0 0 1"/>
    <limit lower="0" upper="0.06" effort="5" velocity="0.05"/>
  </joint>

  <!-- Right finger joint -->
  <joint name="right_finger_joint" type="prismatic">
    <parent link="base_link"/>
    <child link="right_finger"/>
    <origin xyz="-0.042 -0.0185 0.069" rpy="1.5708 0 -1.5708"/>
    <axis xyz="0 0 1"/>
    <limit lower="-0.06" upper="0.0" effort="5" velocity="0.05"/>
  </joint>

</robot>
